<?xml version="1.0" ?>
<!-- =================================================================================== -->
<!-- |    This document was autogenerated by xacro from rsp.urdf.xacro                 | -->
<!-- |    EDITING THIS FILE BY HAND IS NOT RECOMMENDED                                 | -->
<!-- =================================================================================== -->
<robot name="RSP">
  <link name="left_base_link">
    <inertial>
      <origin rpy="0 0 0" xyz="0 0 1.0"/>
      <mass value="1"/>
      <inertia ixx="0.3" ixy="0.0" ixz="0.0" iyy="0.3" iyz="0.0" izz="0.3"/>
    </inertial>
    <visual>
      <origin xyz="0 0 0.5"/>
      <geometry>
        <cylinder length="1" radius="0.1"/>
      </geometry>
      <material name="blue">
        <color rgba="0.0 0.0 0.8 1.0"/>
      </material>
    </visual>
    <collision>
      <origin xyz="0 0 0.5"/>
      <geometry>
        <cylinder length="1" radius="0.1"/>
      </geometry>
      <material name="blue">
        <color rgba="0.0 0.0 0.8 1.0"/>
      </material>
    </collision>
  </link>
  <link name="left_upper_link">
    <inertial>
      <origin rpy="0 0 0" xyz="0 0 1.0"/>
      <mass value="1"/>
      <inertia ixx="0.3" ixy="0.0" ixz="0.0" iyy="0.3" iyz="0.0" izz="0.3"/>
    </inertial>
    <visual>
      <origin xyz="0 0 0.5"/>
      <geometry>
        <cylinder length="1" radius="0.1"/>
      </geometry>
      <material name="white">
        <color rgba="0.8 0.8 0.8 1.0"/>
      </material>
    </visual>
    <collision>
      <origin xyz="0 0 0.5"/>
      <geometry>
        <cylinder length="1" radius="0.1"/>
      </geometry>
      <material name="blue">
        <color rgba="0.0 0.0 0.8 1.0"/>
      </material>
    </collision>
  </link>
  <link name="left_tool"/>
  <joint name="left_shoulder" type="revolute">
    <parent link="left_base_link"/>
    <child link="left_upper_link"/>
    <origin rpy="0 0 0" xyz="0 0 1"/>
    <limit effort="10" lower="-1" upper="1" velocity="1"/>
  </joint>
  <joint name="left_forearm" type="fixed">
    <parent link="left_upper_link"/>
    <child link="left_tool"/>
    <origin rpy="0 0 0" xyz="0 0 1"/>
  </joint>
  <gazebo>
    <plugin filename="libignition-gazebo-joint-state-publisher-system.so" name="ignition::gazebo::systems::JointStatePublisher"/>
  </gazebo>
  <gazebo>
    <plugin filename="rsp_plugin" name="rsp_system">
      <max_velocity>1</max_velocity>
      <joint>left_shoulder</joint>
      <topic>enable</topic>
    </plugin>
  </gazebo>
  <gazebo reference="left_tool">
    <!--
    <sensor name="tool_camera" type="camera">
      <update_rate> 30.0 </update_rate>
      <always_on> 1 </always_on>
      <topic> image </topic>
      <camera name="tool">
        <horizontal_fov> 1.0 </horizontal_fov>
        <image>
          <width> 800 </width>
          <height> 800 </height>
          <format>R8G8B8</format>
        </image>
        <clip>
          <near> 0.02 </near>
          <far> 300 </far>
        </clip>
        <noise>
          <mean> 0.0 </mean>
          <stddev> 0.01 </stddev>
        </noise>
        <visibility_mask>4294967294</visibility_mask>
      </camera>
      <plugin filename="ignition-gazebo-sensors-system" name="ignition::gazebo::systems::Sensors">
  </plugin>
    </sensor>
    -->
    <sensor type="gpu_lidar" name="gpu_lidar">
      <update_rate>40.0</update_rate> 
      <always_on>1</always_on>
      <topic>sonar</topic>
      <visualize>1</visualize>
      <ignition_frame_id>left_tool</ignition_frame_id>
      <ray>
        <scan>
          <horizontal>
            <samples>15</samples>
            <resolution>1.0</resolution>
            <min_angle>-0.1309</min_angle>
            <max_angle>0.1309</max_angle>
          </horizontal>
          <vertical>
            <samples>15</samples>
            <resolution>1.0</resolution>
            <min_angle>-0.1309</min_angle>
            <max_angle>0.1309</max_angle>
          </vertical>
        </scan>
        <range>
          <min>0.02</min>
          <max>4.0</max>
        </range>
        <visibility_mask>4294967294</visibility_mask>
      </ray>
      <plugin filename="ignition-gazebo-sensors-system" name="ignition::gazebo::systems::Sensors">
      </plugin>
    </sensor>
  </gazebo>
  <link name="world"/>
  <joint name="left_base" type="fixed">
    <parent link="world"/>
    <child link="left_base_link"/>
  </joint>
</robot>
