<robot name="maps" xmlns:xacro="http://www.ros.org/wiki/xacro">

  <xacro:include filename="$(find maps_description)/urdf/materials.xacro" />
  <xacro:include filename="$(find maps_description)/urdf/maps.trans" />
  <xacro:include filename="$(find maps_description)/urdf/maps.gazebo" />

  <xacro:macro name="maps" params="name parent offset_x offset_y offset_z offset_roll offset_pitch offset_yaw">

    <link name="${name}_base_link">
      <!-- <inertial>
        <origin xyz="0 0 0" rpy="0 0 0"/>
        <mass value="0.0"/>
        <inertia ixx="0" iyy="0" izz="0" ixy="0" iyz="0" ixz="0"/>
      </inertial>
      <visual>
        <origin xyz="0 0 0" rpy="0 0 0"/>
        <geometry>
        </geometry>
        <material name="black"/>
      </visual>
      <collision>
        <origin xyz="0 0 0" rpy="0 0 0"/>
        <geometry>
        </geometry>
      </collision> -->
    </link>

    <link name="${name}_bottom_plate">
      <inertial>
        <origin xyz="0.028700074056251957 -0.05628457208855371 0.11139109245941702" rpy="0 0 0"/>
        <mass value="0.038950716927574694"/>
        <inertia ixx="5e-05" iyy="5.7e-05" izz="7e-06" ixy="-0.0" iyz="0.0" ixz="0.0"/>
      </inertial>
      <visual>
        <origin xyz="0 0 0" rpy="0 0 0"/>
        <geometry>
          <mesh filename="file://$(find maps_description)/meshes/bottom_plate.stl" scale="0.001 0.001 0.001"/>
        </geometry>
        <material name="black"/>
      </visual>
      <collision>
        <origin xyz="0 0 0" rpy="0 0 0"/>
        <geometry>
          <mesh filename="file://$(find maps_description)/meshes/bottom_plate.stl" scale="0.001 0.001 0.001"/>
        </geometry>
      </collision>
    </link>

    <link name="${name}_Stepper_Housing_1">
      <inertial>
        <origin xyz="1.733766377811849e-05 0.03974239387012183 0.043506004361799196" rpy="0 0 0"/>
        <mass value="0.200297888849439"/>
        <inertia ixx="0.0005" iyy="0.000505" izz="0.000211" ixy="-2e-06" iyz="-2.1e-05" ixz="1e-05"/>
      </inertial>
      <visual>
        <origin xyz="-0.0287 0.059285 -0.048891" rpy="0 0 0"/>
        <geometry>
          <mesh filename="file://$(find maps_description)/meshes/Stepper_Housing_1.stl" scale="0.001 0.001 0.001"/>
        </geometry>
        <material name="black"/>
      </visual>
      <collision>
        <origin xyz="-0.0287 0.059285 -0.048891" rpy="0 0 0"/>
        <geometry>
          <mesh filename="file://$(find maps_description)/meshes/Stepper_Housing_1.stl" scale="0.001 0.001 0.001"/>
        </geometry>
      </collision>
    </link>

    <link name="${name}_Stepper_Motor_2">
      <inertial>
        <origin xyz="-0.02087857142042189 0.014407736892748543 0.013003084922047756" rpy="0 0 0"/>
        <mass value="0.5441132868332024"/>
        <inertia ixx="0.000152" iyy="0.000151" izz="0.000153" ixy="0.0" iyz="-0.0" ixz="0.0"/>
      </inertial>
      <visual>
        <origin xyz="-0.049606 0.045344 -0.111388" rpy="0 0 0"/>
        <geometry>
          <mesh filename="file://$(find maps_description)/meshes/Stepper_Motor_2.stl" scale="0.001 0.001 0.001"/>
        </geometry>
        <material name="silver"/>
      </visual>
      <collision>
        <origin xyz="-0.049606 0.045344 -0.111388" rpy="0 0 0"/>
        <geometry>
          <mesh filename="file://$(find maps_description)/meshes/Stepper_Motor_2.stl" scale="0.001 0.001 0.001"/>
        </geometry>
      </collision>
    </link>

    <link name="${name}_Stepper_Motor_Pulley_2">
      <inertial>
        <origin xyz="0.00014872218127425646 -0.0028059988982639585 0.05055790681907549" rpy="0 0 0"/>
        <mass value="0.0030564891358110494"/>
        <inertia ixx="0.0" iyy="0.0" izz="0.0" ixy="0.0" iyz="-0.0" ixz="0.0"/>
      </inertial>
      <visual>
        <origin xyz="-0.0287 -0.011715 -0.073891" rpy="0 0 0"/>
        <geometry>
          <mesh filename="file://$(find maps_description)/meshes/Stepper_Motor_Pulley_2.stl" scale="0.001 0.001 0.001"/>
        </geometry>
        <material name="silver"/>
      </visual>
      <collision>
        <origin xyz="-0.0287 -0.011715 -0.073891" rpy="0 0 0"/>
        <geometry>
          <mesh filename="file://$(find maps_description)/meshes/Stepper_Motor_Pulley_2.stl" scale="0.001 0.001 0.001"/>
        </geometry>
      </collision>
    </link>

    <link name="${name}_Stepper_Motor_1">
      <inertial>
        <origin xyz="-0.020878571420421887 0.01440773689274864 0.025003084922047586" rpy="0 0 0"/>
        <mass value="0.5441132868332024"/>
        <inertia ixx="0.000152" iyy="0.000151" izz="0.000153" ixy="0.0" iyz="-0.0" ixz="0.0"/>
      </inertial>
      <visual>
        <origin xyz="-0.049606 0.045344 -0.048888" rpy="0 0 0"/>
        <geometry>
          <mesh filename="file://$(find maps_description)/meshes/Stepper_Motor_1.stl" scale="0.001 0.001 0.001"/>
        </geometry>
        <material name="silver"/>
      </visual>
      <collision>
        <origin xyz="-0.049606 0.045344 -0.048888" rpy="0 0 0"/>
        <geometry>
          <mesh filename="file://$(find maps_description)/meshes/Stepper_Motor_1.stl" scale="0.001 0.001 0.001"/>
        </geometry>
      </collision>
    </link>

    <link name="${name}_Stepper_Motor_Pulley_1">
      <inertial>
        <origin xyz="-5.7740303404777565e-05 -0.008805998898263884 0.0001487405844412537" rpy="0 0 0"/>
        <mass value="0.0030564891358110494"/>
        <inertia ixx="0.0" iyy="0.0" izz="0.0" ixy="0.0" iyz="0.0" ixz="-0.0"/>
      </inertial>
      <visual>
        <origin xyz="-0.0287 -0.011715 -0.073891" rpy="0 0 0"/>
        <geometry>
          <mesh filename="file://$(find maps_description)/meshes/Stepper_Motor_Pulley_1.stl" scale="0.001 0.001 0.001"/>
        </geometry>
        <material name="silver"/>
      </visual>
      <collision>
        <origin xyz="-0.0287 -0.011715 -0.073891" rpy="0 0 0"/>
        <geometry>
          <mesh filename="file://$(find maps_description)/meshes/Stepper_Motor_Pulley_1.stl" scale="0.001 0.001 0.001"/>
        </geometry>
      </collision>
    </link>

    <link name="${name}_Housing_Half_Right_1">
      <inertial>
        <origin xyz="-0.015753834019128818 0.00807676983000056 -0.055751666594499136" rpy="0 0 0"/>
        <mass value="0.03618811857879113"/>
        <inertia ixx="7.6e-05" iyy="7.4e-05" izz="1.2e-05" ixy="-1e-06" iyz="-3e-06" ixz="-0.0"/>
      </inertial>
      <visual>
        <origin xyz="-0.054412 0.011344 -0.043888" rpy="0 0 0"/>
        <geometry>
          <mesh filename="file://$(find maps_description)/meshes/Housing_Half_Right_1.stl" scale="0.001 0.001 0.001"/>
        </geometry>
        <material name="black"/>
      </visual>
      <collision>
        <origin xyz="-0.054412 0.011344 -0.043888" rpy="0 0 0"/>
        <geometry>
          <mesh filename="file://$(find maps_description)/meshes/Housing_Half_Right_1.stl" scale="0.001 0.001 0.001"/>
        </geometry>
      </collision>
    </link>

    <link name="${name}_Lid_1">
      <inertial>
        <origin xyz="-0.021151562988249682 -0.0024511558531786215 0.05892507507140977" rpy="0 0 0"/>
        <mass value="0.009187360459117536"/>
        <inertia ixx="1.1e-05" iyy="1.2e-05" izz="1e-06" ixy="0.0" iyz="-1e-06" ixz="0.0"/>
      </inertial>
      <visual>
        <origin xyz="-0.053812 -0.025156 0.066112" rpy="0 0 0"/>
        <geometry>
          <mesh filename="file://$(find maps_description)/meshes/Lid_1.stl" scale="0.001 0.001 0.001"/>
        </geometry>
        <material name="black"/>
      </visual>
      <collision>
        <origin xyz="-0.053812 -0.025156 0.066112" rpy="0 0 0"/>
        <geometry>
          <mesh filename="file://$(find maps_description)/meshes/Lid_1.stl" scale="0.001 0.001 0.001"/>
        </geometry>
      </collision>
    </link>

    <link name="${name}_Heat_Set_Nitinol_Tubing_1">
      <inertial>
        <origin xyz="0.013366557969331724 2.5787753891830245e-07 -1.2661123537550408e-08" rpy="0 0 0"/>
        <mass value="0.0013649495549052447"/>
        <inertia ixx="0.0" iyy="0.0" izz="0.0" ixy="-0.0" iyz="0.0" ixz="-0.0"/>
      </inertial>
      <visual>
        <origin xyz="-0.014706 -0.00794 3e-06" rpy="0 0 0"/>
        <geometry>
          <mesh filename="file://$(find maps_description)/meshes/Heat_Set_Nitinol_Tubing_1.stl" scale="0.001 0.001 0.001"/>
        </geometry>
        <material name="silver"/>
      </visual>
      <collision>
        <origin xyz="-0.014706 -0.00794 3e-06" rpy="0 0 0"/>
        <geometry>
          <mesh filename="file://$(find maps_description)/meshes/Heat_Set_Nitinol_Tubing_1.stl" scale="0.001 0.001 0.001"/>
        </geometry>
      </collision>
    </link>

    <link name="${name}_Clamp_1">
      <inertial>
        <origin xyz="-0.04910599472849593 -0.006490413917958411 0.031091296731927072" rpy="0 0 0"/>
        <mass value="0.0004050623246577962"/>
        <inertia ixx="0.0" iyy="0.0" izz="0.0" ixy="0.0" iyz="0.0" ixz="-0.0"/>
      </inertial>
      <visual>
        <origin xyz="-0.092112 -0.015881 0.071823" rpy="0 0 0"/>
        <geometry>
          <mesh filename="file://$(find maps_description)/meshes/Clamp_1.stl" scale="0.001 0.001 0.001"/>
        </geometry>
        <material name="silver"/>
      </visual>
      <collision>
        <origin xyz="-0.092112 -0.015881 0.071823" rpy="0 0 0"/>
        <geometry>
          <mesh filename="file://$(find maps_description)/meshes/Clamp_1.stl" scale="0.001 0.001 0.001"/>
        </geometry>
      </collision>
    </link>

    <link name="${name}_9271K713_Torsion_Spring_1">
      <inertial>
        <origin xyz="-0.04587815379893997 -0.005191137446164394 0.05995234757403412" rpy="0 0 0"/>
        <mass value="0.00032691523230906554"/>
        <inertia ixx="0.0" iyy="0.0" izz="0.0" ixy="0.0" iyz="-0.0" ixz="-0.0"/>
      </inertial>
      <visual>
        <origin xyz="-0.08886 -0.011717 0.091848" rpy="0 0 0"/>
        <geometry>
          <mesh filename="file://$(find maps_description)/meshes/9271K713_Torsion_Spring_1.stl" scale="0.001 0.001 0.001"/>
        </geometry>
        <material name="silver"/>
      </visual>
      <collision>
        <origin xyz="-0.08886 -0.011717 0.091848" rpy="0 0 0"/>
        <geometry>
          <mesh filename="file://$(find maps_description)/meshes/9271K713_Torsion_Spring_1.stl" scale="0.001 0.001 0.001"/>
        </geometry>
      </collision>
    </link>

    <link name="${name}_Carriage_1">
      <inertial>
        <origin xyz="-0.030067310222141604 -0.012791984068765925 -0.0007101623118073164" rpy="0 0 0"/>
        <mass value="0.005608507543620901"/>
        <inertia ixx="0.0" iyy="0.0" izz="0.0" ixy="0.0" iyz="0.0" ixz="-0.0"/>
      </inertial>
      <visual>
        <origin xyz="-0.073212 -0.015881 0.039665" rpy="0 0 0"/>
        <geometry>
          <mesh filename="file://$(find maps_description)/meshes/Carriage_1.stl" scale="0.001 0.001 0.001"/>
        </geometry>
        <material name="silver"/>
      </visual>
      <collision>
        <origin xyz="-0.073212 -0.015881 0.039665" rpy="0 0 0"/>
        <geometry>
          <mesh filename="file://$(find maps_description)/meshes/Carriage_1.stl" scale="0.001 0.001 0.001"/>
        </geometry>
      </collision>
    </link>

    <link name="${name}_Encoder_1">
      <inertial>
        <origin xyz="-0.0163358433032059 -0.00726671029354733 0.0014768820366421718" rpy="0 0 0"/>
        <mass value="0.0059021295354430466"/>
        <inertia ixx="0.0" iyy="0.0" izz="0.0" ixy="-0.0" iyz="-0.0" ixz="-0.0"/>
      </inertial>
      <visual>
        <origin xyz="-0.073212 -0.015881 6e-06" rpy="0 0 0"/>
        <geometry>
          <mesh filename="file://$(find maps_description)/meshes/Encoder_1.stl" scale="0.001 0.001 0.001"/>
        </geometry>
        <material name="silver"/>
      </visual>
      <collision>
        <origin xyz="-0.073212 -0.015881 6e-06" rpy="0 0 0"/>
        <geometry>
          <mesh filename="file://$(find maps_description)/meshes/Encoder_1.stl" scale="0.001 0.001 0.001"/>
        </geometry>
      </collision>
    </link>

    <link name="${name}_Housing_Half_Left_1">
      <inertial>
        <origin xyz="-0.018099267665483827 -0.02307870475773183 0.042790560700989036" rpy="0 0 0"/>
        <mass value="0.020164852093154183"/>
        <inertia ixx="2e-05" iyy="1.8e-05" izz="3e-06" ixy="0.0" iyz="-1e-06" ixz="1e-06"/>
      </inertial>
      <visual>
        <origin xyz="-0.037412 -0.022156 0.068612" rpy="0 0 0"/>
        <geometry>
          <mesh filename="file://$(find maps_description)/meshes/Housing_Half_Left_1.stl" scale="0.001 0.001 0.001"/>
        </geometry>
        <material name="black"/>
      </visual>
      <collision>
        <origin xyz="-0.037412 -0.022156 0.068612" rpy="0 0 0"/>
        <geometry>
          <mesh filename="file://$(find maps_description)/meshes/Housing_Half_Left_1.stl" scale="0.001 0.001 0.001"/>
        </geometry>
      </collision>
    </link>

    <joint name="${name}_joint_0" type="fixed">
      <parent link="${parent}"/>
      <child link="${name}_base_link"/>
      <origin xyz="${offset_x} ${offset_y} ${offset_z}" rpy="${offset_roll} ${offset_pitch} ${offset_yaw}"/>
    </joint>

    <joint name="${name}_Rigid 117" type="fixed">
      <origin xyz="0.00 0.00 0.060" rpy="1.57079632368 0 0"/>
      <parent link="${name}_base_link"/>
      <child link="${name}_bottom_plate"/>
    </joint>

    <joint name="${name}_Rigid 118" type="fixed">
      <origin xyz="0.0287 -0.059285 0.048891" rpy="0 0 0"/>
      <parent link="${name}_bottom_plate"/>
      <child link="${name}_Stepper_Housing_1"/>
    </joint>

    <joint name="${name}_Rigid 119" type="fixed">
      <origin xyz="0.049606 -0.045344 0.111388" rpy="0 0 0"/>
      <parent link="${name}_bottom_plate"/>
      <child link="${name}_Stepper_Motor_2"/>
    </joint>

    <joint name="${name}_Rigid 120" type="fixed">
      <origin xyz="-0.020906 0.057059 -0.037497" rpy="0 0 0"/>
      <parent link="${name}_Stepper_Motor_2"/>
      <child link="${name}_Stepper_Motor_Pulley_2"/>
    </joint>

    <joint name="${name}_Rigid 121" type="fixed">
      <origin xyz="0.049606 -0.045344 0.048888" rpy="0 0 0"/>
      <parent link="${name}_bottom_plate"/>
      <child link="${name}_Stepper_Motor_1"/>
    </joint>

    <joint name="${name}_Rigid 122" type="fixed">
      <origin xyz="-0.020906 0.057059 0.025003" rpy="0 0 0"/>
      <parent link="${name}_Stepper_Motor_1"/>
      <child link="${name}_Stepper_Motor_Pulley_1"/>
    </joint>

    <joint name="${name}_Rigid 123" type="fixed">
      <origin xyz="0.025712 0.047941 -0.005003" rpy="0 0 0"/>
      <parent link="${name}_Stepper_Housing_1"/>
      <child link="${name}_Housing_Half_Right_1"/>
    </joint>

    <joint name="${name}_Rigid 125" type="fixed">
      <origin xyz="-0.0006 0.0365 -0.11" rpy="0 0 0"/>
      <parent link="${name}_Housing_Half_Right_1"/>
      <child link="${name}_Lid_1"/>
    </joint>

    <joint name="${name}_Nitinol Rotation" type="continuous">
      <origin xyz="-0.022706 -0.014216 0.068609" rpy="0 0 0"/>
      <parent link="${name}_Housing_Half_Left_1"/>
      <child link="${name}_Heat_Set_Nitinol_Tubing_1"/>
      <axis xyz="1.0 0.0 0.0"/>
    </joint>

    <joint name="${name}_Rigid 127" type="fixed">
      <origin xyz="0.0189 0.0 -0.032158" rpy="0 0 0"/>
      <parent link="${name}_Carriage_1"/>
      <child link="${name}_Clamp_1"/>
    </joint>

    <joint name="${name}_Rigid 128" type="fixed">
      <origin xyz="0.015648 -0.004164 -0.052183" rpy="0 0 0"/>
      <parent link="${name}_Carriage_1"/>
      <child link="${name}_9271K713_Torsion_Spring_1"/>
    </joint>

    <joint name="${name}_Clamp Rotation" type="continuous">
      <origin xyz="0.0188 0.027225 -0.083553" rpy="0 0 0"/>
      <parent link="${name}_Housing_Half_Right_1"/>
      <child link="${name}_Carriage_1"/>
      <axis xyz="-1.0 -0.0 -0.0"/>
    </joint>

    <joint name="${name}_Rigid 130" type="fixed">
      <origin xyz="0.0188 0.027225 -0.043894" rpy="0 0 0"/>
      <parent link="${name}_Housing_Half_Right_1"/>
      <child link="${name}_Encoder_1"/>
    </joint>

    <joint name="${name}_Rigid 131" type="fixed">
      <origin xyz="-0.017 0.0335 -0.1125" rpy="0 0 0"/>
      <parent link="${name}_Housing_Half_Right_1"/>
      <child link="${name}_Housing_Half_Left_1"/>
    </joint>

  </xacro:macro>

</robot>
