<?xml version="1.0" ?>
<!-- =================================================================================== -->
<!-- |    This document was autogenerated by xacro from endo360.urdf.xacro             | -->
<!-- |    EDITING THIS FILE BY HAND IS NOT RECOMMENDED                                 | -->
<!-- =================================================================================== -->
<robot name="robot">
  <link name="world"/>
  <!-- 
    <link name = "${parent}"/>
    -->
  <!--  Dummy joint for the base of the tool.-->
  <joint name="world_endo360_joint" type="fixed">
    <parent link="world"/>
    <child link="endo360_link_0"/>
    <origin rpy="0 0 0" xyz="0 0 0"/>
  </joint>
  <!-- link0-->
  <link name="endo360_link_0">
    <visual>
      <origin rpy="0 0 0" xyz="0 0 0"/>
      <geometry>
        <mesh filename="file:///home/nightrider/Documents/JHU/rsp/rsp_clean_ws/install/suture_tool_description/share/suture_tool_description/meshes/endo360-l7.dae"/>
      </geometry>
      <material name="White"/>
    </visual>
    <collision>
      <origin rpy="0 0 0" xyz="0 0 0"/>
      <geometry>
        <mesh filename="file:///home/nightrider/Documents/JHU/rsp/rsp_clean_ws/install/suture_tool_description/share/suture_tool_description/meshes/endo360-l7.dae"/>
      </geometry>
    </collision>
    <inertial>
      <mass value="1e-5"/>
      <origin rpy="0 0 0" xyz="0 0 0"/>
      <inertia ixx="1e-6" ixy="0" ixz="0" iyy="1e-6" iyz="0" izz="1e-6"/>
    </inertial>
  </link>
  <!--   revoluate joint between link_0 and link_1-->
  <joint name="endo360_joint_1" type="revolute">
    <parent link="endo360_link_0"/>
    <child link="endo360_link_1"/>
    <origin rpy="0 0 0" xyz="0.00 0.0000 0.56736"/>
    <axis xyz="0 1 0"/>
    <limit effort="300" lower="-0.5235987755982988" upper="0.5235987755982988" velocity="10"/>
  </joint>
  <!-- link1-->
  <link name="endo360_link_1">
    <visual>
      <origin rpy="0 0 0" xyz="0 0 0"/>
      <geometry>
        <mesh filename="file:///home/nightrider/Documents/JHU/rsp/rsp_clean_ws/install/suture_tool_description/share/suture_tool_description/meshes/endo360-l8.dae"/>
      </geometry>
      <material name="Red"/>
    </visual>
    <collision>
      <origin rpy="0 3.141592653589793 0" xyz="0 0 0.015"/>
      <geometry>
        <mesh filename="file:///home/nightrider/Documents/JHU/rsp/rsp_clean_ws/install/suture_tool_description/share/suture_tool_description/meshes/endo360-l8.dae"/>
      </geometry>
    </collision>
    <inertial>
      <mass value="1e-5"/>
      <origin rpy="0 0 0" xyz="0 0 0"/>
      <inertia ixx="1e-6" ixy="0" ixz="0" iyy="1e-6" iyz="0" izz="1e-6"/>
    </inertial>
  </link>
  <!-- joint between link_1 and needle -->
  <joint name="endo360_joint_3" type="revolute">
    <parent link="endo360_link_1"/>
    <child link="endo360_needle"/>
    <origin rpy="0 0 0" xyz="0.00 0.0025 0.04600"/>
    <axis xyz="0 1 0"/>
    <limit effort="300" lower="-3.141592653589793" upper="3.141592653589793" velocity="10"/>
  </joint>
  <!-- needle link -->
  <link name="endo360_needle">
    <visual>
      <origin rpy="0 0 0" xyz="0 -0.003 0"/>
      <geometry>
        <mesh filename="file:///home/nightrider/Documents/JHU/rsp/rsp_clean_ws/install/suture_tool_description/share/suture_tool_description/meshes/needle.stl" scale="0.001 0.001 0.001"/>
      </geometry>
    </visual>
    <collision>
      <origin rpy="0 0 0" xyz="0 -0.003 0"/>
      <geometry>
        <mesh filename="file:///home/nightrider/Documents/JHU/rsp/rsp_clean_ws/install/suture_tool_description/share/suture_tool_description/meshes/needle.stl" scale="0.001 0.001 0.001"/>
      </geometry>
    </collision>
    <inertial>
      <mass value="1e-5"/>
      <origin rpy="0 0 0" xyz="0 0 0"/>
      <inertia ixx="1e-6" ixy="0" ixz="0" iyy="1e-6" iyz="0" izz="1e-6"/>
    </inertial>
  </link>
  <gazebo>
    <plugin filename="libignition-gazebo-joint-state-publisher-system.so" name="ignition::gazebo::systems::JointStatePublisher"/>
  </gazebo>
</robot>
